WARNING:django.request:Not Found: /favicon.ico
WARNING:django.request:Not Found: /favicon.ico
WARNING:django.request:Not Found: /favicon.ico
WARNING:django.request:Not Found: /favicon.ico
WARNING:django.request:Not Found: /favicon.ico
WARNING:django.request:Not Found: /favicon.ico
WARNING:root:{'leads': {'status': [{'id': 8298849, 'status_id': 68706394}]}}
WARNING:django.request:Not Found: /favicon.ico
INFO:django.utils.autoreload:/media/dmitry/892692f6-5784-45bf-99db-b9bc8507ff9d/dmitry/projects/vaso-site/vaso/user/views.py changed, reloading.
ERROR:django.request:Internal Server Error: /catalog/bouquet/1
Traceback (most recent call last):
  File "/media/dmitry/892692f6-5784-45bf-99db-b9bc8507ff9d/dmitry/projects/vaso-site/venv/lib/python3.10/site-packages/django/core/handlers/exception.py", line 55, in inner
    response = get_response(request)
  File "/media/dmitry/892692f6-5784-45bf-99db-b9bc8507ff9d/dmitry/projects/vaso-site/venv/lib/python3.10/site-packages/django/core/handlers/base.py", line 197, in _get_response
    response = wrapped_callback(request, *callback_args, **callback_kwargs)
  File "/media/dmitry/892692f6-5784-45bf-99db-b9bc8507ff9d/dmitry/projects/vaso-site/venv/lib/python3.10/site-packages/django/views/generic/base.py", line 104, in view
    return self.dispatch(request, *args, **kwargs)
  File "/media/dmitry/892692f6-5784-45bf-99db-b9bc8507ff9d/dmitry/projects/vaso-site/venv/lib/python3.10/site-packages/django/views/generic/base.py", line 143, in dispatch
    return handler(request, *args, **kwargs)
  File "/media/dmitry/892692f6-5784-45bf-99db-b9bc8507ff9d/dmitry/projects/vaso-site/vaso/catalog/views.py", line 72, in post
    payment_url = create_payment(new_order)
  File "/media/dmitry/892692f6-5784-45bf-99db-b9bc8507ff9d/dmitry/projects/vaso-site/vaso/orders/yookassa.py", line 46, in create_payment
    response = Payment.create(request)
  File "/media/dmitry/892692f6-5784-45bf-99db-b9bc8507ff9d/dmitry/projects/vaso-site/venv/lib/python3.10/site-packages/yookassa/payment.py", line 66, in create
    response = instance.client.request(HttpVerb.POST, path, None, headers, params_object)
  File "/media/dmitry/892692f6-5784-45bf-99db-b9bc8507ff9d/dmitry/projects/vaso-site/venv/lib/python3.10/site-packages/yookassa/client.py", line 51, in request
    raw_response = self.execute(body, method, path, query_params, request_headers)
  File "/media/dmitry/892692f6-5784-45bf-99db-b9bc8507ff9d/dmitry/projects/vaso-site/venv/lib/python3.10/site-packages/yookassa/client.py", line 82, in execute
    self.log_response(raw_response.content, self.get_response_info(raw_response), raw_response.headers)
  File "/media/dmitry/892692f6-5784-45bf-99db-b9bc8507ff9d/dmitry/projects/vaso-site/venv/lib/python3.10/site-packages/yookassa/client.py", line 169, in get_response_info
    "raise_for_status": response.raise_for_status(),
  File "/media/dmitry/892692f6-5784-45bf-99db-b9bc8507ff9d/dmitry/projects/vaso-site/venv/lib/python3.10/site-packages/requests/models.py", line 1024, in raise_for_status
    raise HTTPError(http_error_msg, response=self)
requests.exceptions.HTTPError: 401 Client Error:  for url: https://api.yookassa.ru/v3/payments
INFO:django.utils.autoreload:/media/dmitry/892692f6-5784-45bf-99db-b9bc8507ff9d/dmitry/projects/vaso-site/vaso/vaso/settings.py changed, reloading.
ERROR:django.request:Internal Server Error: /catalog/bouquet/1
Traceback (most recent call last):
  File "/media/dmitry/892692f6-5784-45bf-99db-b9bc8507ff9d/dmitry/projects/vaso-site/venv/lib/python3.10/site-packages/django/core/handlers/exception.py", line 55, in inner
    response = get_response(request)
  File "/media/dmitry/892692f6-5784-45bf-99db-b9bc8507ff9d/dmitry/projects/vaso-site/venv/lib/python3.10/site-packages/django/core/handlers/base.py", line 197, in _get_response
    response = wrapped_callback(request, *callback_args, **callback_kwargs)
  File "/media/dmitry/892692f6-5784-45bf-99db-b9bc8507ff9d/dmitry/projects/vaso-site/venv/lib/python3.10/site-packages/django/views/generic/base.py", line 104, in view
    return self.dispatch(request, *args, **kwargs)
  File "/media/dmitry/892692f6-5784-45bf-99db-b9bc8507ff9d/dmitry/projects/vaso-site/venv/lib/python3.10/site-packages/django/views/generic/base.py", line 143, in dispatch
    return handler(request, *args, **kwargs)
  File "/media/dmitry/892692f6-5784-45bf-99db-b9bc8507ff9d/dmitry/projects/vaso-site/vaso/catalog/views.py", line 72, in post
    payment_url = create_payment(new_order)
  File "/media/dmitry/892692f6-5784-45bf-99db-b9bc8507ff9d/dmitry/projects/vaso-site/vaso/orders/yookassa.py", line 46, in create_payment
    response = Payment.create(request)
  File "/media/dmitry/892692f6-5784-45bf-99db-b9bc8507ff9d/dmitry/projects/vaso-site/venv/lib/python3.10/site-packages/yookassa/payment.py", line 66, in create
    response = instance.client.request(HttpVerb.POST, path, None, headers, params_object)
  File "/media/dmitry/892692f6-5784-45bf-99db-b9bc8507ff9d/dmitry/projects/vaso-site/venv/lib/python3.10/site-packages/yookassa/client.py", line 51, in request
    raw_response = self.execute(body, method, path, query_params, request_headers)
  File "/media/dmitry/892692f6-5784-45bf-99db-b9bc8507ff9d/dmitry/projects/vaso-site/venv/lib/python3.10/site-packages/yookassa/client.py", line 82, in execute
    self.log_response(raw_response.content, self.get_response_info(raw_response), raw_response.headers)
  File "/media/dmitry/892692f6-5784-45bf-99db-b9bc8507ff9d/dmitry/projects/vaso-site/venv/lib/python3.10/site-packages/yookassa/client.py", line 169, in get_response_info
    "raise_for_status": response.raise_for_status(),
  File "/media/dmitry/892692f6-5784-45bf-99db-b9bc8507ff9d/dmitry/projects/vaso-site/venv/lib/python3.10/site-packages/requests/models.py", line 1024, in raise_for_status
    raise HTTPError(http_error_msg, response=self)
requests.exceptions.HTTPError: 401 Client Error:  for url: https://api.yookassa.ru/v3/payments
INFO:django.utils.autoreload:/media/dmitry/892692f6-5784-45bf-99db-b9bc8507ff9d/dmitry/projects/vaso-site/vaso/vaso/settings.py changed, reloading.
INFO:django.utils.autoreload:/media/dmitry/892692f6-5784-45bf-99db-b9bc8507ff9d/dmitry/projects/vaso-site/vaso/user/views.py changed, reloading.
INFO:django.utils.autoreload:/media/dmitry/892692f6-5784-45bf-99db-b9bc8507ff9d/dmitry/projects/vaso-site/vaso/orders/views.py changed, reloading.
INFO:django.utils.autoreload:/media/dmitry/892692f6-5784-45bf-99db-b9bc8507ff9d/dmitry/projects/vaso-site/vaso/orders/views.py changed, reloading.
INFO:django.utils.autoreload:/media/dmitry/892692f6-5784-45bf-99db-b9bc8507ff9d/dmitry/projects/vaso-site/vaso/orders/views.py changed, reloading.
INFO:django.utils.autoreload:/media/dmitry/892692f6-5784-45bf-99db-b9bc8507ff9d/dmitry/projects/vaso-site/vaso/orders/views.py changed, reloading.
INFO:django.utils.autoreload:/media/dmitry/892692f6-5784-45bf-99db-b9bc8507ff9d/dmitry/projects/vaso-site/vaso/orders/views.py changed, reloading.
INFO:django.utils.autoreload:/media/dmitry/892692f6-5784-45bf-99db-b9bc8507ff9d/dmitry/projects/vaso-site/vaso/orders/views.py changed, reloading.
INFO:django.utils.autoreload:/media/dmitry/892692f6-5784-45bf-99db-b9bc8507ff9d/dmitry/projects/vaso-site/vaso/orders/views.py changed, reloading.
INFO:django.utils.autoreload:/media/dmitry/892692f6-5784-45bf-99db-b9bc8507ff9d/dmitry/projects/vaso-site/vaso/orders/views.py changed, reloading.
INFO:django.utils.autoreload:/media/dmitry/892692f6-5784-45bf-99db-b9bc8507ff9d/dmitry/projects/vaso-site/vaso/orders/views.py changed, reloading.
INFO:django.utils.autoreload:/media/dmitry/892692f6-5784-45bf-99db-b9bc8507ff9d/dmitry/projects/vaso-site/vaso/orders/views.py changed, reloading.
INFO:django.utils.autoreload:/media/dmitry/892692f6-5784-45bf-99db-b9bc8507ff9d/dmitry/projects/vaso-site/vaso/orders/views.py changed, reloading.
INFO:django.utils.autoreload:/media/dmitry/892692f6-5784-45bf-99db-b9bc8507ff9d/dmitry/projects/vaso-site/vaso/orders/views.py changed, reloading.
INFO:django.utils.autoreload:/media/dmitry/892692f6-5784-45bf-99db-b9bc8507ff9d/dmitry/projects/vaso-site/vaso/orders/views.py changed, reloading.
INFO:django.utils.autoreload:/media/dmitry/892692f6-5784-45bf-99db-b9bc8507ff9d/dmitry/projects/vaso-site/vaso/orders/views.py changed, reloading.
INFO:django.utils.autoreload:/media/dmitry/892692f6-5784-45bf-99db-b9bc8507ff9d/dmitry/projects/vaso-site/vaso/orders/views.py changed, reloading.
INFO:django.utils.autoreload:/media/dmitry/892692f6-5784-45bf-99db-b9bc8507ff9d/dmitry/projects/vaso-site/vaso/orders/views.py changed, reloading.
INFO:django.utils.autoreload:/media/dmitry/892692f6-5784-45bf-99db-b9bc8507ff9d/dmitry/projects/vaso-site/vaso/orders/views.py changed, reloading.
INFO:django.utils.autoreload:/media/dmitry/892692f6-5784-45bf-99db-b9bc8507ff9d/dmitry/projects/vaso-site/vaso/orders/views.py changed, reloading.
ERROR:django.request:Internal Server Error: /catalog/bouquet/1
Traceback (most recent call last):
  File "/media/dmitry/892692f6-5784-45bf-99db-b9bc8507ff9d/dmitry/projects/vaso-site/venv/lib/python3.10/site-packages/django/db/models/fields/__init__.py", line 2123, in get_prep_value
    return int(value)
TypeError: int() argument must be a string, a bytes-like object or a real number, not 'SimpleLazyObject'

The above exception was the direct cause of the following exception:

Traceback (most recent call last):
  File "/media/dmitry/892692f6-5784-45bf-99db-b9bc8507ff9d/dmitry/projects/vaso-site/venv/lib/python3.10/site-packages/django/core/handlers/exception.py", line 55, in inner
    response = get_response(request)
  File "/media/dmitry/892692f6-5784-45bf-99db-b9bc8507ff9d/dmitry/projects/vaso-site/venv/lib/python3.10/site-packages/django/core/handlers/base.py", line 197, in _get_response
    response = wrapped_callback(request, *callback_args, **callback_kwargs)
  File "/media/dmitry/892692f6-5784-45bf-99db-b9bc8507ff9d/dmitry/projects/vaso-site/venv/lib/python3.10/site-packages/django/views/generic/base.py", line 104, in view
    return self.dispatch(request, *args, **kwargs)
  File "/media/dmitry/892692f6-5784-45bf-99db-b9bc8507ff9d/dmitry/projects/vaso-site/venv/lib/python3.10/site-packages/django/views/generic/base.py", line 143, in dispatch
    return handler(request, *args, **kwargs)
  File "/media/dmitry/892692f6-5784-45bf-99db-b9bc8507ff9d/dmitry/projects/vaso-site/vaso/catalog/views.py", line 54, in post
    profile = UserProfile.objects.get(user=request.user)
  File "/media/dmitry/892692f6-5784-45bf-99db-b9bc8507ff9d/dmitry/projects/vaso-site/venv/lib/python3.10/site-packages/django/db/models/manager.py", line 87, in manager_method
    return getattr(self.get_queryset(), name)(*args, **kwargs)
  File "/media/dmitry/892692f6-5784-45bf-99db-b9bc8507ff9d/dmitry/projects/vaso-site/venv/lib/python3.10/site-packages/django/db/models/query.py", line 635, in get
    clone = self._chain() if self.query.combinator else self.filter(*args, **kwargs)
  File "/media/dmitry/892692f6-5784-45bf-99db-b9bc8507ff9d/dmitry/projects/vaso-site/venv/lib/python3.10/site-packages/django/db/models/query.py", line 1476, in filter
    return self._filter_or_exclude(False, args, kwargs)
  File "/media/dmitry/892692f6-5784-45bf-99db-b9bc8507ff9d/dmitry/projects/vaso-site/venv/lib/python3.10/site-packages/django/db/models/query.py", line 1494, in _filter_or_exclude
    clone._filter_or_exclude_inplace(negate, args, kwargs)
  File "/media/dmitry/892692f6-5784-45bf-99db-b9bc8507ff9d/dmitry/projects/vaso-site/venv/lib/python3.10/site-packages/django/db/models/query.py", line 1501, in _filter_or_exclude_inplace
    self._query.add_q(Q(*args, **kwargs))
  File "/media/dmitry/892692f6-5784-45bf-99db-b9bc8507ff9d/dmitry/projects/vaso-site/venv/lib/python3.10/site-packages/django/db/models/sql/query.py", line 1609, in add_q
    clause, _ = self._add_q(q_object, self.used_aliases)
  File "/media/dmitry/892692f6-5784-45bf-99db-b9bc8507ff9d/dmitry/projects/vaso-site/venv/lib/python3.10/site-packages/django/db/models/sql/query.py", line 1641, in _add_q
    child_clause, needed_inner = self.build_filter(
  File "/media/dmitry/892692f6-5784-45bf-99db-b9bc8507ff9d/dmitry/projects/vaso-site/venv/lib/python3.10/site-packages/django/db/models/sql/query.py", line 1555, in build_filter
    condition = self.build_lookup(lookups, col, value)
  File "/media/dmitry/892692f6-5784-45bf-99db-b9bc8507ff9d/dmitry/projects/vaso-site/venv/lib/python3.10/site-packages/django/db/models/sql/query.py", line 1385, in build_lookup
    lookup = lookup_class(lhs, rhs)
  File "/media/dmitry/892692f6-5784-45bf-99db-b9bc8507ff9d/dmitry/projects/vaso-site/venv/lib/python3.10/site-packages/django/db/models/lookups.py", line 30, in __init__
    self.rhs = self.get_prep_lookup()
  File "/media/dmitry/892692f6-5784-45bf-99db-b9bc8507ff9d/dmitry/projects/vaso-site/venv/lib/python3.10/site-packages/django/db/models/fields/related_lookups.py", line 156, in get_prep_lookup
    self.rhs = target_field.get_prep_value(self.rhs)
  File "/media/dmitry/892692f6-5784-45bf-99db-b9bc8507ff9d/dmitry/projects/vaso-site/venv/lib/python3.10/site-packages/django/db/models/fields/__init__.py", line 2125, in get_prep_value
    raise e.__class__(
TypeError: Field 'id' expected a number but got <SimpleLazyObject: <django.contrib.auth.models.AnonymousUser object at 0x744b89c2c370>>.
ERROR:django.request:Internal Server Error: /catalog/bouquet/1
Traceback (most recent call last):
  File "/media/dmitry/892692f6-5784-45bf-99db-b9bc8507ff9d/dmitry/projects/vaso-site/venv/lib/python3.10/site-packages/django/db/models/fields/__init__.py", line 2123, in get_prep_value
    return int(value)
TypeError: int() argument must be a string, a bytes-like object or a real number, not 'SimpleLazyObject'

The above exception was the direct cause of the following exception:

Traceback (most recent call last):
  File "/media/dmitry/892692f6-5784-45bf-99db-b9bc8507ff9d/dmitry/projects/vaso-site/venv/lib/python3.10/site-packages/django/core/handlers/exception.py", line 55, in inner
    response = get_response(request)
  File "/media/dmitry/892692f6-5784-45bf-99db-b9bc8507ff9d/dmitry/projects/vaso-site/venv/lib/python3.10/site-packages/django/core/handlers/base.py", line 197, in _get_response
    response = wrapped_callback(request, *callback_args, **callback_kwargs)
  File "/media/dmitry/892692f6-5784-45bf-99db-b9bc8507ff9d/dmitry/projects/vaso-site/venv/lib/python3.10/site-packages/django/views/generic/base.py", line 104, in view
    return self.dispatch(request, *args, **kwargs)
  File "/media/dmitry/892692f6-5784-45bf-99db-b9bc8507ff9d/dmitry/projects/vaso-site/venv/lib/python3.10/site-packages/django/views/generic/base.py", line 143, in dispatch
    return handler(request, *args, **kwargs)
  File "/media/dmitry/892692f6-5784-45bf-99db-b9bc8507ff9d/dmitry/projects/vaso-site/vaso/catalog/views.py", line 54, in post
    profile = UserProfile.objects.get(user=request.user)
  File "/media/dmitry/892692f6-5784-45bf-99db-b9bc8507ff9d/dmitry/projects/vaso-site/venv/lib/python3.10/site-packages/django/db/models/manager.py", line 87, in manager_method
    return getattr(self.get_queryset(), name)(*args, **kwargs)
  File "/media/dmitry/892692f6-5784-45bf-99db-b9bc8507ff9d/dmitry/projects/vaso-site/venv/lib/python3.10/site-packages/django/db/models/query.py", line 635, in get
    clone = self._chain() if self.query.combinator else self.filter(*args, **kwargs)
  File "/media/dmitry/892692f6-5784-45bf-99db-b9bc8507ff9d/dmitry/projects/vaso-site/venv/lib/python3.10/site-packages/django/db/models/query.py", line 1476, in filter
    return self._filter_or_exclude(False, args, kwargs)
  File "/media/dmitry/892692f6-5784-45bf-99db-b9bc8507ff9d/dmitry/projects/vaso-site/venv/lib/python3.10/site-packages/django/db/models/query.py", line 1494, in _filter_or_exclude
    clone._filter_or_exclude_inplace(negate, args, kwargs)
  File "/media/dmitry/892692f6-5784-45bf-99db-b9bc8507ff9d/dmitry/projects/vaso-site/venv/lib/python3.10/site-packages/django/db/models/query.py", line 1501, in _filter_or_exclude_inplace
    self._query.add_q(Q(*args, **kwargs))
  File "/media/dmitry/892692f6-5784-45bf-99db-b9bc8507ff9d/dmitry/projects/vaso-site/venv/lib/python3.10/site-packages/django/db/models/sql/query.py", line 1609, in add_q
    clause, _ = self._add_q(q_object, self.used_aliases)
  File "/media/dmitry/892692f6-5784-45bf-99db-b9bc8507ff9d/dmitry/projects/vaso-site/venv/lib/python3.10/site-packages/django/db/models/sql/query.py", line 1641, in _add_q
    child_clause, needed_inner = self.build_filter(
  File "/media/dmitry/892692f6-5784-45bf-99db-b9bc8507ff9d/dmitry/projects/vaso-site/venv/lib/python3.10/site-packages/django/db/models/sql/query.py", line 1555, in build_filter
    condition = self.build_lookup(lookups, col, value)
  File "/media/dmitry/892692f6-5784-45bf-99db-b9bc8507ff9d/dmitry/projects/vaso-site/venv/lib/python3.10/site-packages/django/db/models/sql/query.py", line 1385, in build_lookup
    lookup = lookup_class(lhs, rhs)
  File "/media/dmitry/892692f6-5784-45bf-99db-b9bc8507ff9d/dmitry/projects/vaso-site/venv/lib/python3.10/site-packages/django/db/models/lookups.py", line 30, in __init__
    self.rhs = self.get_prep_lookup()
  File "/media/dmitry/892692f6-5784-45bf-99db-b9bc8507ff9d/dmitry/projects/vaso-site/venv/lib/python3.10/site-packages/django/db/models/fields/related_lookups.py", line 156, in get_prep_lookup
    self.rhs = target_field.get_prep_value(self.rhs)
  File "/media/dmitry/892692f6-5784-45bf-99db-b9bc8507ff9d/dmitry/projects/vaso-site/venv/lib/python3.10/site-packages/django/db/models/fields/__init__.py", line 2125, in get_prep_value
    raise e.__class__(
TypeError: Field 'id' expected a number but got <SimpleLazyObject: <django.contrib.auth.models.AnonymousUser object at 0x744b7a70a410>>.
ERROR:django.request:Internal Server Error: /catalog/bouquet/1
Traceback (most recent call last):
  File "/media/dmitry/892692f6-5784-45bf-99db-b9bc8507ff9d/dmitry/projects/vaso-site/venv/lib/python3.10/site-packages/django/db/models/fields/__init__.py", line 2123, in get_prep_value
    return int(value)
TypeError: int() argument must be a string, a bytes-like object or a real number, not 'SimpleLazyObject'

The above exception was the direct cause of the following exception:

Traceback (most recent call last):
  File "/media/dmitry/892692f6-5784-45bf-99db-b9bc8507ff9d/dmitry/projects/vaso-site/venv/lib/python3.10/site-packages/django/core/handlers/exception.py", line 55, in inner
    response = get_response(request)
  File "/media/dmitry/892692f6-5784-45bf-99db-b9bc8507ff9d/dmitry/projects/vaso-site/venv/lib/python3.10/site-packages/django/core/handlers/base.py", line 197, in _get_response
    response = wrapped_callback(request, *callback_args, **callback_kwargs)
  File "/media/dmitry/892692f6-5784-45bf-99db-b9bc8507ff9d/dmitry/projects/vaso-site/venv/lib/python3.10/site-packages/django/views/generic/base.py", line 104, in view
    return self.dispatch(request, *args, **kwargs)
  File "/media/dmitry/892692f6-5784-45bf-99db-b9bc8507ff9d/dmitry/projects/vaso-site/venv/lib/python3.10/site-packages/django/views/generic/base.py", line 143, in dispatch
    return handler(request, *args, **kwargs)
  File "/media/dmitry/892692f6-5784-45bf-99db-b9bc8507ff9d/dmitry/projects/vaso-site/vaso/catalog/views.py", line 54, in post
    profile = UserProfile.objects.get(user=request.user)
  File "/media/dmitry/892692f6-5784-45bf-99db-b9bc8507ff9d/dmitry/projects/vaso-site/venv/lib/python3.10/site-packages/django/db/models/manager.py", line 87, in manager_method
    return getattr(self.get_queryset(), name)(*args, **kwargs)
  File "/media/dmitry/892692f6-5784-45bf-99db-b9bc8507ff9d/dmitry/projects/vaso-site/venv/lib/python3.10/site-packages/django/db/models/query.py", line 635, in get
    clone = self._chain() if self.query.combinator else self.filter(*args, **kwargs)
  File "/media/dmitry/892692f6-5784-45bf-99db-b9bc8507ff9d/dmitry/projects/vaso-site/venv/lib/python3.10/site-packages/django/db/models/query.py", line 1476, in filter
    return self._filter_or_exclude(False, args, kwargs)
  File "/media/dmitry/892692f6-5784-45bf-99db-b9bc8507ff9d/dmitry/projects/vaso-site/venv/lib/python3.10/site-packages/django/db/models/query.py", line 1494, in _filter_or_exclude
    clone._filter_or_exclude_inplace(negate, args, kwargs)
  File "/media/dmitry/892692f6-5784-45bf-99db-b9bc8507ff9d/dmitry/projects/vaso-site/venv/lib/python3.10/site-packages/django/db/models/query.py", line 1501, in _filter_or_exclude_inplace
    self._query.add_q(Q(*args, **kwargs))
  File "/media/dmitry/892692f6-5784-45bf-99db-b9bc8507ff9d/dmitry/projects/vaso-site/venv/lib/python3.10/site-packages/django/db/models/sql/query.py", line 1609, in add_q
    clause, _ = self._add_q(q_object, self.used_aliases)
  File "/media/dmitry/892692f6-5784-45bf-99db-b9bc8507ff9d/dmitry/projects/vaso-site/venv/lib/python3.10/site-packages/django/db/models/sql/query.py", line 1641, in _add_q
    child_clause, needed_inner = self.build_filter(
  File "/media/dmitry/892692f6-5784-45bf-99db-b9bc8507ff9d/dmitry/projects/vaso-site/venv/lib/python3.10/site-packages/django/db/models/sql/query.py", line 1555, in build_filter
    condition = self.build_lookup(lookups, col, value)
  File "/media/dmitry/892692f6-5784-45bf-99db-b9bc8507ff9d/dmitry/projects/vaso-site/venv/lib/python3.10/site-packages/django/db/models/sql/query.py", line 1385, in build_lookup
    lookup = lookup_class(lhs, rhs)
  File "/media/dmitry/892692f6-5784-45bf-99db-b9bc8507ff9d/dmitry/projects/vaso-site/venv/lib/python3.10/site-packages/django/db/models/lookups.py", line 30, in __init__
    self.rhs = self.get_prep_lookup()
  File "/media/dmitry/892692f6-5784-45bf-99db-b9bc8507ff9d/dmitry/projects/vaso-site/venv/lib/python3.10/site-packages/django/db/models/fields/related_lookups.py", line 156, in get_prep_lookup
    self.rhs = target_field.get_prep_value(self.rhs)
  File "/media/dmitry/892692f6-5784-45bf-99db-b9bc8507ff9d/dmitry/projects/vaso-site/venv/lib/python3.10/site-packages/django/db/models/fields/__init__.py", line 2125, in get_prep_value
    raise e.__class__(
TypeError: Field 'id' expected a number but got <SimpleLazyObject: <django.contrib.auth.models.AnonymousUser object at 0x744b881ddbd0>>.
INFO:django.utils.autoreload:/media/dmitry/892692f6-5784-45bf-99db-b9bc8507ff9d/dmitry/projects/vaso-site/vaso/user/views.py changed, reloading.
INFO:django.utils.autoreload:/media/dmitry/892692f6-5784-45bf-99db-b9bc8507ff9d/dmitry/projects/vaso-site/vaso/user/views.py changed, reloading.
INFO:django.utils.autoreload:/media/dmitry/892692f6-5784-45bf-99db-b9bc8507ff9d/dmitry/projects/vaso-site/vaso/user/views.py changed, reloading.
INFO:django.utils.autoreload:/media/dmitry/892692f6-5784-45bf-99db-b9bc8507ff9d/dmitry/projects/vaso-site/vaso/user/views.py changed, reloading.
INFO:django.utils.autoreload:/media/dmitry/892692f6-5784-45bf-99db-b9bc8507ff9d/dmitry/projects/vaso-site/vaso/user/urls.py changed, reloading.
INFO:django.utils.autoreload:/media/dmitry/892692f6-5784-45bf-99db-b9bc8507ff9d/dmitry/projects/vaso-site/vaso/user/views.py changed, reloading.
INFO:django.utils.autoreload:/media/dmitry/892692f6-5784-45bf-99db-b9bc8507ff9d/dmitry/projects/vaso-site/vaso/user/views.py changed, reloading.
WARNING:django.request:Not Found: /favicon.ico
INFO:django.utils.autoreload:/home/user/test_project/new-vaso/vaso/user/views.py changed, reloading.
INFO:django.utils.autoreload:/home/user/test_project/new-vaso/vaso/user/views.py changed, reloading.
INFO:django.utils.autoreload:/home/user/test_project/new-vaso/vaso/user/views.py changed, reloading.
INFO:django.utils.autoreload:/home/user/test_project/new-vaso/vaso/user/views.py changed, reloading.
INFO:django.utils.autoreload:/home/user/test_project/new-vaso/vaso/user/views.py changed, reloading.
WARNING:django.request:Not Found: /catalog/bouquet/undefined
INFO:django.utils.autoreload:/home/user/test_project/new-vaso/vaso/user/views.py changed, reloading.
WARNING:django.request:Not Found: /catalog/bouquet/undefined
WARNING:django.request:Not Found: /catalog/bouquet/undefined
WARNING:django.request:Forbidden: /users/api/check_code_and_pay/
ERROR:django.request:Internal Server Error: /users/api/check_code_and_pay/
Traceback (most recent call last):
  File "/home/user/test_project/new-vaso/venv/lib/python3.12/site-packages/django/db/backends/utils.py", line 105, in _execute
    return self.cursor.execute(sql, params)
           ^^^^^^^^^^^^^^^^^^^^^^^^^^^^^^^^
  File "/home/user/test_project/new-vaso/venv/lib/python3.12/site-packages/django/db/backends/sqlite3/base.py", line 354, in execute
    return super().execute(query, params)
           ^^^^^^^^^^^^^^^^^^^^^^^^^^^^^^
sqlite3.IntegrityError: UNIQUE constraint failed: auth_user.username

The above exception was the direct cause of the following exception:

Traceback (most recent call last):
  File "/home/user/test_project/new-vaso/venv/lib/python3.12/site-packages/django/core/handlers/exception.py", line 55, in inner
    response = get_response(request)
               ^^^^^^^^^^^^^^^^^^^^^
  File "/home/user/test_project/new-vaso/venv/lib/python3.12/site-packages/django/core/handlers/base.py", line 197, in _get_response
    response = wrapped_callback(request, *callback_args, **callback_kwargs)
               ^^^^^^^^^^^^^^^^^^^^^^^^^^^^^^^^^^^^^^^^^^^^^^^^^^^^^^^^^^^^
  File "/home/user/test_project/new-vaso/venv/lib/python3.12/site-packages/django/views/decorators/csrf.py", line 65, in _view_wrapper
    return view_func(request, *args, **kwargs)
           ^^^^^^^^^^^^^^^^^^^^^^^^^^^^^^^^^^^
  File "/home/user/test_project/new-vaso/venv/lib/python3.12/site-packages/django/views/generic/base.py", line 104, in view
    return self.dispatch(request, *args, **kwargs)
           ^^^^^^^^^^^^^^^^^^^^^^^^^^^^^^^^^^^^^^^
  File "/home/user/test_project/new-vaso/venv/lib/python3.12/site-packages/rest_framework/views.py", line 509, in dispatch
    response = self.handle_exception(exc)
               ^^^^^^^^^^^^^^^^^^^^^^^^^^
  File "/home/user/test_project/new-vaso/venv/lib/python3.12/site-packages/rest_framework/views.py", line 469, in handle_exception
    self.raise_uncaught_exception(exc)
  File "/home/user/test_project/new-vaso/venv/lib/python3.12/site-packages/rest_framework/views.py", line 480, in raise_uncaught_exception
    raise exc
  File "/home/user/test_project/new-vaso/venv/lib/python3.12/site-packages/rest_framework/views.py", line 506, in dispatch
    response = handler(request, *args, **kwargs)
               ^^^^^^^^^^^^^^^^^^^^^^^^^^^^^^^^^
  File "/home/user/test_project/new-vaso/vaso/user/views.py", line 93, in post
    profile = get_or_create_user(phone, name)
              ^^^^^^^^^^^^^^^^^^^^^^^^^^^^^^^
  File "/home/user/test_project/new-vaso/vaso/user/utils.py", line 39, in get_or_create_user
    new_user = User.objects.create_user(username=phone, first_name=name)
               ^^^^^^^^^^^^^^^^^^^^^^^^^^^^^^^^^^^^^^^^^^^^^^^^^^^^^^^^^
  File "/home/user/test_project/new-vaso/venv/lib/python3.12/site-packages/django/contrib/auth/models.py", line 162, in create_user
    return self._create_user(username, email, password, **extra_fields)
           ^^^^^^^^^^^^^^^^^^^^^^^^^^^^^^^^^^^^^^^^^^^^^^^^^^^^^^^^^^^^
  File "/home/user/test_project/new-vaso/venv/lib/python3.12/site-packages/django/contrib/auth/models.py", line 156, in _create_user
    user.save(using=self._db)
  File "/home/user/test_project/new-vaso/venv/lib/python3.12/site-packages/django/contrib/auth/base_user.py", line 62, in save
    super().save(*args, **kwargs)
  File "/home/user/test_project/new-vaso/venv/lib/python3.12/site-packages/django/db/models/base.py", line 891, in save
    self.save_base(
  File "/home/user/test_project/new-vaso/venv/lib/python3.12/site-packages/django/db/models/base.py", line 997, in save_base
    updated = self._save_table(
              ^^^^^^^^^^^^^^^^^
  File "/home/user/test_project/new-vaso/venv/lib/python3.12/site-packages/django/db/models/base.py", line 1160, in _save_table
    results = self._do_insert(
              ^^^^^^^^^^^^^^^^
  File "/home/user/test_project/new-vaso/venv/lib/python3.12/site-packages/django/db/models/base.py", line 1201, in _do_insert
    return manager._insert(
           ^^^^^^^^^^^^^^^^
  File "/home/user/test_project/new-vaso/venv/lib/python3.12/site-packages/django/db/models/manager.py", line 87, in manager_method
    return getattr(self.get_queryset(), name)(*args, **kwargs)
           ^^^^^^^^^^^^^^^^^^^^^^^^^^^^^^^^^^^^^^^^^^^^^^^^^^^
  File "/home/user/test_project/new-vaso/venv/lib/python3.12/site-packages/django/db/models/query.py", line 1847, in _insert
    return query.get_compiler(using=using).execute_sql(returning_fields)
           ^^^^^^^^^^^^^^^^^^^^^^^^^^^^^^^^^^^^^^^^^^^^^^^^^^^^^^^^^^^^^
  File "/home/user/test_project/new-vaso/venv/lib/python3.12/site-packages/django/db/models/sql/compiler.py", line 1836, in execute_sql
    cursor.execute(sql, params)
  File "/home/user/test_project/new-vaso/venv/lib/python3.12/site-packages/django/db/backends/utils.py", line 122, in execute
    return super().execute(sql, params)
           ^^^^^^^^^^^^^^^^^^^^^^^^^^^^
  File "/home/user/test_project/new-vaso/venv/lib/python3.12/site-packages/django/db/backends/utils.py", line 79, in execute
    return self._execute_with_wrappers(
           ^^^^^^^^^^^^^^^^^^^^^^^^^^^^
  File "/home/user/test_project/new-vaso/venv/lib/python3.12/site-packages/django/db/backends/utils.py", line 92, in _execute_with_wrappers
    return executor(sql, params, many, context)
           ^^^^^^^^^^^^^^^^^^^^^^^^^^^^^^^^^^^^
  File "/home/user/test_project/new-vaso/venv/lib/python3.12/site-packages/django/db/backends/utils.py", line 100, in _execute
    with self.db.wrap_database_errors:
  File "/home/user/test_project/new-vaso/venv/lib/python3.12/site-packages/django/db/utils.py", line 91, in __exit__
    raise dj_exc_value.with_traceback(traceback) from exc_value
  File "/home/user/test_project/new-vaso/venv/lib/python3.12/site-packages/django/db/backends/utils.py", line 105, in _execute
    return self.cursor.execute(sql, params)
           ^^^^^^^^^^^^^^^^^^^^^^^^^^^^^^^^
  File "/home/user/test_project/new-vaso/venv/lib/python3.12/site-packages/django/db/backends/sqlite3/base.py", line 354, in execute
    return super().execute(query, params)
           ^^^^^^^^^^^^^^^^^^^^^^^^^^^^^^
django.db.utils.IntegrityError: UNIQUE constraint failed: auth_user.username
WARNING:django.request:Forbidden: /users/api/check_code_and_pay/
INFO:django.utils.autoreload:/home/user/test_project/new-vaso/vaso/user/views.py changed, reloading.
WARNING:django.request:Forbidden: /users/api/check_code_and_pay/
INFO:django.utils.autoreload:/home/user/test_project/new-vaso/vaso/user/urls.py changed, reloading.
INFO:django.utils.autoreload:/home/user/test_project/new-vaso/vaso/user/urls.py changed, reloading.
WARNING:django.request:Forbidden: /users/api/check_code_and_pay/
INFO:django.utils.autoreload:/home/user/test_project/new-vaso/vaso/user/views.py changed, reloading.
INFO:django.utils.autoreload:/home/user/test_project/new-vaso/vaso/user/views.py changed, reloading.
INFO:django.utils.autoreload:/home/user/test_project/new-vaso/vaso/user/views.py changed, reloading.
INFO:django.utils.autoreload:/home/user/test_project/new-vaso/vaso/user/views.py changed, reloading.
INFO:django.utils.autoreload:/home/user/test_project/new-vaso/vaso/user/views.py changed, reloading.
INFO:django.utils.autoreload:/home/user/test_project/new-vaso/vaso/user/views.py changed, reloading.
INFO:django.utils.autoreload:/home/user/test_project/new-vaso/vaso/user/views.py changed, reloading.
INFO:django.utils.autoreload:/home/user/test_project/new-vaso/vaso/user/views.py changed, reloading.
INFO:django.utils.autoreload:/home/user/test_project/new-vaso/vaso/user/views.py changed, reloading.
INFO:django.utils.autoreload:/home/user/test_project/new-vaso/vaso/user/views.py changed, reloading.
INFO:django.utils.autoreload:/home/user/test_project/new-vaso/vaso/user/views.py changed, reloading.
INFO:django.utils.autoreload:/home/user/test_project/new-vaso/vaso/user/views.py changed, reloading.
INFO:django.utils.autoreload:/home/user/test_project/new-vaso/vaso/user/views.py changed, reloading.
ERROR:django.request:Internal Server Error: /users/api/check_code_and_pay/
Traceback (most recent call last):
  File "/home/user/test_project/new-vaso/venv/lib/python3.12/site-packages/django/db/backends/utils.py", line 105, in _execute
    return self.cursor.execute(sql, params)
           ^^^^^^^^^^^^^^^^^^^^^^^^^^^^^^^^
  File "/home/user/test_project/new-vaso/venv/lib/python3.12/site-packages/django/db/backends/sqlite3/base.py", line 354, in execute
    return super().execute(query, params)
           ^^^^^^^^^^^^^^^^^^^^^^^^^^^^^^
sqlite3.IntegrityError: NOT NULL constraint failed: orders.address

The above exception was the direct cause of the following exception:

Traceback (most recent call last):
  File "/home/user/test_project/new-vaso/venv/lib/python3.12/site-packages/django/core/handlers/exception.py", line 55, in inner
    response = get_response(request)
               ^^^^^^^^^^^^^^^^^^^^^
  File "/home/user/test_project/new-vaso/venv/lib/python3.12/site-packages/django/core/handlers/base.py", line 197, in _get_response
    response = wrapped_callback(request, *callback_args, **callback_kwargs)
               ^^^^^^^^^^^^^^^^^^^^^^^^^^^^^^^^^^^^^^^^^^^^^^^^^^^^^^^^^^^^
  File "/home/user/test_project/new-vaso/venv/lib/python3.12/site-packages/django/views/decorators/csrf.py", line 65, in _view_wrapper
    return view_func(request, *args, **kwargs)
           ^^^^^^^^^^^^^^^^^^^^^^^^^^^^^^^^^^^
  File "/home/user/test_project/new-vaso/venv/lib/python3.12/site-packages/django/views/generic/base.py", line 104, in view
    return self.dispatch(request, *args, **kwargs)
           ^^^^^^^^^^^^^^^^^^^^^^^^^^^^^^^^^^^^^^^
  File "/home/user/test_project/new-vaso/venv/lib/python3.12/site-packages/rest_framework/views.py", line 509, in dispatch
    response = self.handle_exception(exc)
               ^^^^^^^^^^^^^^^^^^^^^^^^^^
  File "/home/user/test_project/new-vaso/venv/lib/python3.12/site-packages/rest_framework/views.py", line 469, in handle_exception
    self.raise_uncaught_exception(exc)
  File "/home/user/test_project/new-vaso/venv/lib/python3.12/site-packages/rest_framework/views.py", line 480, in raise_uncaught_exception
    raise exc
  File "/home/user/test_project/new-vaso/venv/lib/python3.12/site-packages/rest_framework/views.py", line 506, in dispatch
    response = handler(request, *args, **kwargs)
               ^^^^^^^^^^^^^^^^^^^^^^^^^^^^^^^^^
  File "/home/user/test_project/new-vaso/vaso/user/views.py", line 133, in post
    new_order = create_order(True, order_data)
                ^^^^^^^^^^^^^^^^^^^^^^^^^^^^^^
  File "/home/user/test_project/new-vaso/vaso/orders/utils.py", line 119, in create_order
    new_order = Order.objects.create(
                ^^^^^^^^^^^^^^^^^^^^^
  File "/home/user/test_project/new-vaso/venv/lib/python3.12/site-packages/django/db/models/manager.py", line 87, in manager_method
    return getattr(self.get_queryset(), name)(*args, **kwargs)
           ^^^^^^^^^^^^^^^^^^^^^^^^^^^^^^^^^^^^^^^^^^^^^^^^^^^
  File "/home/user/test_project/new-vaso/venv/lib/python3.12/site-packages/django/db/models/query.py", line 679, in create
    obj.save(force_insert=True, using=self.db)
  File "/home/user/test_project/new-vaso/venv/lib/python3.12/site-packages/django/db/models/base.py", line 891, in save
    self.save_base(
  File "/home/user/test_project/new-vaso/venv/lib/python3.12/site-packages/django/db/models/base.py", line 997, in save_base
    updated = self._save_table(
              ^^^^^^^^^^^^^^^^^
  File "/home/user/test_project/new-vaso/venv/lib/python3.12/site-packages/django/db/models/base.py", line 1160, in _save_table
    results = self._do_insert(
              ^^^^^^^^^^^^^^^^
  File "/home/user/test_project/new-vaso/venv/lib/python3.12/site-packages/django/db/models/base.py", line 1201, in _do_insert
    return manager._insert(
           ^^^^^^^^^^^^^^^^
  File "/home/user/test_project/new-vaso/venv/lib/python3.12/site-packages/django/db/models/manager.py", line 87, in manager_method
    return getattr(self.get_queryset(), name)(*args, **kwargs)
           ^^^^^^^^^^^^^^^^^^^^^^^^^^^^^^^^^^^^^^^^^^^^^^^^^^^
  File "/home/user/test_project/new-vaso/venv/lib/python3.12/site-packages/django/db/models/query.py", line 1847, in _insert
    return query.get_compiler(using=using).execute_sql(returning_fields)
           ^^^^^^^^^^^^^^^^^^^^^^^^^^^^^^^^^^^^^^^^^^^^^^^^^^^^^^^^^^^^^
  File "/home/user/test_project/new-vaso/venv/lib/python3.12/site-packages/django/db/models/sql/compiler.py", line 1836, in execute_sql
    cursor.execute(sql, params)
  File "/home/user/test_project/new-vaso/venv/lib/python3.12/site-packages/django/db/backends/utils.py", line 122, in execute
    return super().execute(sql, params)
           ^^^^^^^^^^^^^^^^^^^^^^^^^^^^
  File "/home/user/test_project/new-vaso/venv/lib/python3.12/site-packages/django/db/backends/utils.py", line 79, in execute
    return self._execute_with_wrappers(
           ^^^^^^^^^^^^^^^^^^^^^^^^^^^^
  File "/home/user/test_project/new-vaso/venv/lib/python3.12/site-packages/django/db/backends/utils.py", line 92, in _execute_with_wrappers
    return executor(sql, params, many, context)
           ^^^^^^^^^^^^^^^^^^^^^^^^^^^^^^^^^^^^
  File "/home/user/test_project/new-vaso/venv/lib/python3.12/site-packages/django/db/backends/utils.py", line 100, in _execute
    with self.db.wrap_database_errors:
  File "/home/user/test_project/new-vaso/venv/lib/python3.12/site-packages/django/db/utils.py", line 91, in __exit__
    raise dj_exc_value.with_traceback(traceback) from exc_value
  File "/home/user/test_project/new-vaso/venv/lib/python3.12/site-packages/django/db/backends/utils.py", line 105, in _execute
    return self.cursor.execute(sql, params)
           ^^^^^^^^^^^^^^^^^^^^^^^^^^^^^^^^
  File "/home/user/test_project/new-vaso/venv/lib/python3.12/site-packages/django/db/backends/sqlite3/base.py", line 354, in execute
    return super().execute(query, params)
           ^^^^^^^^^^^^^^^^^^^^^^^^^^^^^^
django.db.utils.IntegrityError: NOT NULL constraint failed: orders.address
INFO:django.utils.autoreload:/home/user/test_project/new-vaso/vaso/user/views.py changed, reloading.
